# SOME DESCRIPTIVE TITLE.
# Copyright (C) 2001-2023, Python Software Foundation
# This file is distributed under the same license as the Python package.
# FIRST AUTHOR <EMAIL@ADDRESS>, YEAR.
#
# Translators:
# Leticia Portella <leportella@gmail.com>, 2019
# Rafael Fontenelle <rffontenelle@gmail.com>, 2021
#
#, fuzzy
msgid ""
msgstr ""
"Project-Id-Version: Python 3.7\n"
"Report-Msgid-Bugs-To: \n"
"POT-Creation-Date: 2023-06-23 16:56+0000\n"
"PO-Revision-Date: 2019-09-01 03:31+0000\n"
"Last-Translator: Rafael Fontenelle <rffontenelle@gmail.com>, 2021\n"
"Language-Team: Portuguese (Brazil) (https://app.transifex.com/python-doc/"
"teams/5390/pt_BR/)\n"
"MIME-Version: 1.0\n"
"Content-Type: text/plain; charset=UTF-8\n"
"Content-Transfer-Encoding: 8bit\n"
"Language: pt_BR\n"
"Plural-Forms: nplurals=3; plural=(n == 0 || n == 1) ? 0 : n != 0 && n % "
"1000000 == 0 ? 1 : 2;\n"

#: /home/runner/work/python-docs-tx-translations/python-docs-tx-translations/cpython/Doc/library/asyncio-exceptions.rst:8
msgid "Exceptions"
msgstr "Exceções"

#: /home/runner/work/python-docs-tx-translations/python-docs-tx-translations/cpython/Doc/library/asyncio-exceptions.rst:13
msgid "The operation has exceeded the given deadline."
msgstr "A operação excedeu o prazo estabelecido."

#: /home/runner/work/python-docs-tx-translations/python-docs-tx-translations/cpython/Doc/library/asyncio-exceptions.rst:16
msgid ""
"This exception is different from the builtin :exc:`TimeoutError` exception."
msgstr "Esta exceção é diferente da exceção embutida :exc:`TimeoutError`."

#: /home/runner/work/python-docs-tx-translations/python-docs-tx-translations/cpython/Doc/library/asyncio-exceptions.rst:22
msgid "The operation has been cancelled."
msgstr "A operação foi cancelada."

#: /home/runner/work/python-docs-tx-translations/python-docs-tx-translations/cpython/Doc/library/asyncio-exceptions.rst:24
msgid ""
"This exception can be caught to perform custom operations when asyncio Tasks "
"are cancelled.  In almost all situations the exception must be re-raised."
msgstr ""
"Esta exceção pode ser capturada para executar operações personalizadas "
"quando as tarefas assíncronas são canceladas. Em quase todas as situações, a "
"exceção deve ser levantada novamente."

#: /home/runner/work/python-docs-tx-translations/python-docs-tx-translations/cpython/Doc/library/asyncio-exceptions.rst:30
msgid ""
"This exception is a subclass of :exc:`Exception`, so it can be accidentally "
"suppressed by an overly broad ``try..except`` block::"
msgstr ""

#: /home/runner/work/python-docs-tx-translations/python-docs-tx-translations/cpython/Doc/library/asyncio-exceptions.rst:40
msgid "Instead, the following pattern should be used::"
msgstr ""

#: /home/runner/work/python-docs-tx-translations/python-docs-tx-translations/cpython/Doc/library/asyncio-exceptions.rst:52
msgid "Invalid internal state of :class:`Task` or :class:`Future`."
msgstr "Estado interno inválido de :class:`Task` ou :class:`Future`."

#: /home/runner/work/python-docs-tx-translations/python-docs-tx-translations/cpython/Doc/library/asyncio-exceptions.rst:54
msgid ""
"Can be raised in situations like setting a result value for a *Future* "
"object that already has a result value set."
msgstr ""
"Pode ser levantada em situações como definir um valor de resultado para um "
"objeto *Future* que já tem um valor de resultado definido."

#: /home/runner/work/python-docs-tx-translations/python-docs-tx-translations/cpython/Doc/library/asyncio-exceptions.rst:60
msgid ""
"The \"sendfile\" syscall is not available for the given socket or file type."
msgstr ""
"A *syscall* \"sendfile\" não está disponível para o soquete ou tipo de "
"arquivo fornecido."

#: /home/runner/work/python-docs-tx-translations/python-docs-tx-translations/cpython/Doc/library/asyncio-exceptions.rst:63
msgid "A subclass of :exc:`RuntimeError`."
msgstr "Uma subclasse de :exc:`RuntimeError`."

#: /home/runner/work/python-docs-tx-translations/python-docs-tx-translations/cpython/Doc/library/asyncio-exceptions.rst:68
msgid "The requested read operation did not complete fully."
msgstr "A operação de leitura solicitada não foi totalmente concluída."

#: /home/runner/work/python-docs-tx-translations/python-docs-tx-translations/cpython/Doc/library/asyncio-exceptions.rst:70
msgid "Raised by the :ref:`asyncio stream APIs<asyncio-streams>`."
msgstr "Levantada pelas :ref:`APIs de fluxo de asyncio<asyncio-streams>`."

#: /home/runner/work/python-docs-tx-translations/python-docs-tx-translations/cpython/Doc/library/asyncio-exceptions.rst:72
msgid "This exception is a subclass of :exc:`EOFError`."
msgstr "Esta exceção é uma subclasse de :exc:`EOFError`."

#: /home/runner/work/python-docs-tx-translations/python-docs-tx-translations/cpython/Doc/library/asyncio-exceptions.rst:76
msgid "The total number (:class:`int`) of expected bytes."
msgstr "O número total (:class:`int`) de bytes esperados."

#: /home/runner/work/python-docs-tx-translations/python-docs-tx-translations/cpython/Doc/library/asyncio-exceptions.rst:80
msgid "A string of :class:`bytes` read before the end of stream was reached."
msgstr ""
"Uma string de :class:`bytes` lida antes do final do fluxo ser alcançado."

#: /home/runner/work/python-docs-tx-translations/python-docs-tx-translations/cpython/Doc/library/asyncio-exceptions.rst:85
msgid "Reached the buffer size limit while looking for a separator."
msgstr "Atingiu o limite de tamanho do buffer ao procurar um separador."

#: /home/runner/work/python-docs-tx-translations/python-docs-tx-translations/cpython/Doc/library/asyncio-exceptions.rst:87
msgid "Raised by the :ref:`asyncio stream APIs <asyncio-streams>`."
msgstr "Levantada pelas :ref:`APIs de fluxo de asyncio <asyncio-streams>`."

#: /home/runner/work/python-docs-tx-translations/python-docs-tx-translations/cpython/Doc/library/asyncio-exceptions.rst:91
msgid "The total number of to be consumed bytes."
msgstr "O número total de bytes a serem consumidos."
